Workbook

Sheet Sheet1
A1: Campaign Name | B1: Banner Name | C1: Merchant | D1: Banner | E1: Start Date | F1: End Date | G1: Account Manager | H1: Price
A2: Afiat Lab | B2: Afiat Lab | C2: https://adserver.doctoreto.com/www/delivery/cl.php?bannerid=636&zoneid=0&log=no&sig=b6cf5889ae7d9c83142463102cfc0925f1675a04e297fd00c5616e0664e143ea&dest=https%3A%2F%2Fdoctoreto.com%2Fcenter%2Fafiat-esfehan-lab%2FYgPlyL | D2: https://adserver.doctoreto.com/www/images/b25bb3b18fc8f0e7a863650d8752d095.gif | E2: 1405/03/03 | F2: 1405/06/03 | G2: Shahrzad | H2: 75000000
A3: Ako Hamzeie | B3: Ako Hamzeie PLP | C3: https://adserver.doctoreto.com/www/delivery/cl.php?bannerid=1010&zoneid=0&log=no&sig=5a5cf7772c4f52316542672e33be554be3e8184cc5925df6c619359335dd004d&dest=https%3A%2F%2Fdoctoreto.com%2Fdoctor%2Fdr-ako-hamzei%2FZPrNxp | D3: https://adserver.doctoreto.com/www/images/32a68a02754ef77646006179bb374706.gif | E3: 1405/04/30 | F3: 1405/07/30 | G3: Mohammad | H3: 60000000
A4: Ali Mohammadi Moghadam | B4: Ali Mohammadi Moghadam | C4: https://adserver.doctoreto.com/www/delivery/cl.php?bannerid=596&zoneid=0&log=no&sig=6ac59bb1d5301706044e9581efc46d13ba60a4252da0f9ac729a63b1433156cb&dest=https%3A%2F%2Fdoctoreto.com%2Fdoctor%2Fdr-ali-mohammadi-moghadam%2FqdDYrP | D4: https://adserver.doctoreto.com/www/images/1349ca8569ad1b4c4db041e36398ee08.gif | E4: 1405/04/23 | F4: 1405/08/01 | G4: Ellie | H4: 160000000
A5: Ali Mohammadi Moghadam | B5: Ali Mohammadi Moghadam PLP FagharaT | C5: https://adserver.doctoreto.com/www/delivery/cl.php?bannerid=935&zoneid=0&log=no&sig=62c9dec9f304926d5917edbb9bc99bd1b00c00b51988a83137892a6e3e06135b&dest=https%3A%2F%2Fdoctoreto.com%2Fdoctor%2Fdr-ali-mohammadi-moghadam%2FqdDYrP | D5: https://adserver.doctoreto.com/www/images/3f125a5ba498f9aeec458ca2582c1ccb.gif | E5: 1405/04/23 | F5: 1405/08/01 | G5: Ellie | H5: 165000000
A6: Amir Hossein ShirBan | B6: Dr ShirBan | C6: https://adserver.doctoreto.com/www/delivery/cl.php?bannerid=696&zoneid=0&log=no&sig=62779ec800ca4bafb6c4a223215412516edfe902b6a56e565c172f7a2fa269c8&dest=https%3A%2F%2Fdoctoreto.com%2Fdoctor%2Famir-hossein-shirban%2FZnazEM | D6: https://adserver.doctoreto.com/www/images/011a03284eec135bb5f2bb3e211a580b.gif | E6: 1405/03/26 | F6: 1405/06/26 | G6: Mohammad | H6: 36300000
A7: AmirHossein Emami Meybodi | B7: AmirHossein Emami Meybodi | C7: https://adserver.doctoreto.com/www/delivery/cl.php?bannerid=970&zoneid=0&log=no&sig=394316068b7839373e591cf91982764ee3587fa46898700f3d0a11dcfc5a936a&dest=https%3A%2F%2Fdoctoreto.com%2Fdoctor%2Fdr-amir-hosein-emami-meybodi%2FMzDkKq | D7: https://adserver.doctoreto.com/www/images/2f149ff6e68ff17b082960c4081aba03.gif | E7: 1405/04/28 | F7: 1405/07/28 | G7: Shaghayegh | H7: 100000000
A8: Arta Clinic - KhabazZadeh | B8: Arta Clinic - KhabazZadeh two PLP | C8: https://adserver.doctoreto.com/www/delivery/cl.php?bannerid=1095&zoneid=0&log=no&sig=8b7e94a9b9bdb93d3123ec611fe20f8965f50b1c4fdf90f0a0050a32ae83d330&dest=https%3A%2F%2Fdoctoreto.com%2Fdoctor%2Fdr-ali-khabbazzadeh%2FZAKXVV | D8: https://adserver.doctoreto.com/www/images/fa3a7556063a95c193cabb51da400426.gif | E8: 1405/05/10 | F8: 1405/08/10 | G8: Naser | H8: 143000000
A9: Dr Mohammad Ali Ansari | B9: Dr M.A Ansari | C9: https://adserver.doctoreto.com/www/delivery/cl.php?bannerid=549&zoneid=0&log=no&sig=09c161a618c54065d94d1375348a9aec46df6ee951760af572a472feeee79c1c&dest=https%3A%2F%2Fdoctoreto.com%2Fdoctor%2Fdr-mohammad-ali-ansari%2FMlQRvJ | D9: https://adserver.doctoreto.com/www/images/604f0a115f23b778a2f1a97beb89bfd4.webp | E9: 1406/05/20 | F9: 1405/08/20 | G9: Sanam | H9: 80000000
A10: Dr Sara Arzhang | B10: Dr Sara Arzhang | C10: https://adserver.doctoreto.com/www/delivery/cl.php?bannerid=545&zoneid=0&log=no&sig=f73f24a5dff21d99331502c4735ed5c9dddaac377a055af84920749795d7c1d5&dest=https%3A%2F%2Fdoctoreto.com%2Fdoctor%2Fdr-sara-arjang%2FMLXvgR | D10: https://adserver.doctoreto.com/www/images/7c462a69adb9793b55c42a095a31fade.gif | E10: 1404/11/14 | F10: 1405/07/14 | G10: Sanam | H10: 168000000
A11: Dr - abdulvahab baradaran | B11: Dr - Abdulvahab baradaran | C11: https://adserver.doctoreto.com/www/delivery/cl.php?bannerid=644&zoneid=0&log=no&sig=71a9c21aebc374647e82ced92b490abb3df1c91a35985b779274d9e72eff1a83&dest=https%3A%2F%2Fdoctoreto.com%2Fdoctor%2Fdr-abdolvahab-baradaran%2FqRzXKx | D11: https://adserver.doctoreto.com/www/images/a935e7c584e416681ee1fc92459fa9f2.gif | E11: 1405/03/09 | F11: 1405/06/09 | G11: Shaghayegh | H11: 66000000
A12: Dr. Bambaei Chi | B12: dr. bamaei chi | C12: https://adserver.doctoreto.com/www/delivery/cl.php?bannerid=366&zoneid=0&log=no&sig=4a7b44131961965ad206b0b883e8a278ae0faeaed4717272d8520370f822dc15&dest=https%3A%2F%2Fdoctoreto.com%2Fdoctor%2Fdr-paridokht-bambaei-chi%2FGeRDDM | D12: https://adserver.doctoreto.com/www/images/63b01efe2557b069f4e4665bb6d3c2a5.webp | E12: 1404/04/31 | F12: 1404/07/30 | G12: Naser | H12: 40100000
A13: Aban psycology clinic | B13: Aban | C13: https://adserver.doctoreto.com/www/delivery/cl.php?bannerid=450&zoneid=0&log=no&sig=dd0d5d47897769810acdf7c20649c489f63ea020e3b5150814d7f5b955350ab5&dest=https%3A%2F%2Fdoctoreto.com%2Fcenter%2Faban-shiraz-clinic%2FAbprqZ%3FsearchedFrom%3DheaderAutoFill | D13: https://adserver.doctoreto.com/www/images/ad6b4f2f6e1949de8a4e4b538dec3b5f.jpg | E13: 1405/06/09 | F13: 1405/09/09 | G13: Mohammad | H13: 44000000
A14: Abbas Behrad | B14: Dr Abbad Behrad | C14: https://adserver.doctoreto.com/www/delivery/cl.php?bannerid=1147&zoneid=0&log=no&sig=6fef0a8d618aabf8d63b8e7d95c1464c8c74918d4701d05524674f29f2226ad8&dest=https%3A%2F%2Fdoctoreto.com%2Fdoctor%2Fdr-abbas-behrad%2FMzzQzM | D14: https://adserver.doctoreto.com/www/images/e710a0e114f35edae0d39179efe0e121.gif | E14: 1405/05/29 | F14: 1405/08/29 | G14: Ellie | H14: 70000000
A15: Aradid | B15: Aradid | C15: https://adserver.doctoreto.com/www/delivery/cl.php?bannerid=1192&zoneid=0&log=no&sig=5c03e94db37fdc306538de93ebdd2465aa10d885cd8e0448c3401f607e99e6b2&dest=https%3A%2F%2Fdoctoreto.com%2Fdoctor%2Falireza-khoub-yari%2FZPdnbQ | D15: https://adserver.doctoreto.com/www/images/b5f1abd7e1936446fa7f0793bb5d13b9.gif | E15: 1405/06/04 | F15: 1405/09/04
A16: Arghavan Clinic | B16: Arghavan Clinic | C16: https://adserver.doctoreto.com/www/delivery/cl.php?bannerid=612&zoneid=0&log=no&sig=a5fef04815e4fdfbbe1ad5e120bf8696968b683930629c6249ec8bdbcba4dcd5&dest=https%3A%2F%2Fdoctoreto.com%2Fcenter%2Farghavan-shiraz-infirmary%2FMQavNK | D16: https://adserver.doctoreto.com/www/images/0f3cdb69996646a660c2998454b02a8e.gif | E16: 1405/06/07 | F16: 1405/09/07 | G16: Sara | H16: 190000000
A17: Arghavan Clinic | B17: Arghavan Clinic Desktop | C17: https://adserver.doctoreto.com/www/delivery/cl.php?bannerid=1232&zoneid=0&log=no&sig=daebd280fb159f114decd57cebf8e8dd9bc214236f80ecdbd71aea68aaffc12b&dest=https%3A%2F%2Fdoctoreto.com%2Fcenter%2Farghavan-shiraz-infirmary%2FMQavNK%3F_gl%3D | D17: https://adserver.doctoreto.com/www/images/14e19a01414f6e2eb1a79c6ff1ac357b.gif | E17: 1405/06/07 | F17: 1405/09/07 | G17: Sara | H17: 190000000
A18: Arghavan Clinic | B18: Arghavan Clinic Mobile | C18: https://adserver.doctoreto.com/www/delivery/cl.php?bannerid=1237&zoneid=0&log=no&sig=ee08d92e8b5543166905679f2397f247d99ec9f1471b9c993077d22bb7b574ce&dest=https%3A%2F%2Fdoctoreto.com%2Fcenter%2Farghavan-shiraz-infirmary%2FMQavNK%3F_gl%3D | D18: https://adserver.doctoreto.com/www/images/889a6f77e87cbbfdd5c4ad157b540702.gif | E18: 1405/06/07 | F18: 1405/09/07 | G18: Sara | H18: 190000000
A19: Avina Clinic | B19: Avina Clinic Karaj | C19: https://adserver.doctoreto.com/www/delivery/cl.php?bannerid=716&zoneid=0&log=no&sig=39940605c92ee689cc06c8f0baf1fd2071b14163e17468209a307105f9780bb3&dest=https%3A%2F%2Fdoctoreto.com%2Fcenter%2Favina-karaj-clinic%2FAeXzBG | D19: https://adserver.doctoreto.com/www/images/b85be36b4f5831d0c55dd7b8d4330f5c.gif | E19: 1405/03/27 | F19: 1405/06/27 | G19: Mohammad
A20: Avina Clinic Tehran | B20: Avina Clinic Tehran | C20: https://adserver.doctoreto.com/www/delivery/cl.php?bannerid=1183&zoneid=0&log=no&sig=aab822690cc07bec70aade3c80539e35466cad071ee0471324c08644fd27a136&dest=https%3A%2F%2Fdoctoreto.com%2Fcenter%2Favina-tehran-clinic%2FAeyaXb | D20: https://adserver.doctoreto.com/www/images/fc3344e43e46a3371b2aef2c4375da18.gif | E20: 1405/06/01 | F20: 1405/09/01 | G20: Ellie
A21: Behrouz Besharat | B21: DR Besharat | C21: https://adserver.doctoreto.com/www/delivery/cl.php?bannerid=662&zoneid=0&log=no&sig=bb57008062b03e68adfc0fafa64d6ac567a4627297e9ff468c4621505b558e75&dest=https%3A%2F%2Fdoctoreto.com%2Fdoctor%2Fdr-behrooz-besharat%2FMmPLJX | D21: https://adserver.doctoreto.com/www/images/eb590c39fc9be830f1b190a64b30e2aa.gif | E21: 1405/03/17 | F21: 1405/06/17 | G21: Sanam | H21: 78000000
A22: Clinic Sepida | B22: Clinic Sepida | C22: https://adserver.doctoreto.com/www/delivery/cl.php?bannerid=910&zoneid=0&log=no&sig=5e6ad142f46a9484fc8f324892af8346dd052cdf374ade63677387a363547c30&dest=https%3A%2F%2Fdoctoreto.com%2Fcenter%2Fsepida-tehran-clinic%2FZyJOyo | D22: https://adserver.doctoreto.com/www/images/e87ec79e0ec1dde1532d113d94414657.gif | E22: 1405/04/24 | F22: 1405/07/24 | G22: Shaghayegh | H22: 66000000
A23: Diabet Kourosh | B23: Diabet Kouro$H | C23: https://adserver.doctoreto.com/www/delivery/cl.php?bannerid=1188&zoneid=0&log=no&sig=8bee8bf2a35808588888f78696dd3e5e8a7b521b03b681da7d6e2ed9a81eebe6&dest=https%3A%2F%2Fdoctoreto.com%2Fcenter%2Fkurosh-clinic%2FAkVegO | D23: https://adserver.doctoreto.com/www/images/0d5d8064f5fdf917169227994ef3d696.png | E23: 1405/06/02 | F23: 1405/09/02
A24: Dr - Afshin Tajali | B24: DR - Afshin Tajali | C24: https://adserver.doctoreto.com/www/delivery/cl.php?bannerid=491&zoneid=0&log=no&sig=9ce1cdaa3362cd1cc7c3fc3ec18147c900d9ea1431259d734c93b2d40b7857f6&dest=https%3A%2F%2Fdoctoreto.com%2Fdoctor%2Fdr-afshin-tajalli%2FqkbKAZ | D24: https://adserver.doctoreto.com/www/images/bc17533ac25821a49b7b0f2341bb1a0d.webp | E24: 1404/09/26 | F24: 1404/12/26 | G24: Sanam | H24: 50000000
A25: Dr - Arsham Azar Baad | B25: Dr Arsham Azar Baad | C25: https://adserver.doctoreto.com/www/delivery/cl.php?bannerid=529&zoneid=0&log=no&sig=45a6bc46563231da01b2427d5bd1c3dee0a8444f21f1923bca3acc0129125c3f&dest=https%3A%2F%2Fdoctoreto.com%2Fdoctor%2Fdr-arsham-azarbad%2FZpgDRw | D25: https://adserver.doctoreto.com/www/images/f22ffd09452ccff6ccb872871c268e5e.webp | E25: 1404/11/04 | F25: 1405/02/04 | G25: Nastaran | H25: 45000000
A26: Dr - Hamid HaghShenas | B26: Dr Hamid HaghShenas | C26: https://adserver.doctoreto.com/www/delivery/cl.php?bannerid=481&zoneid=0&log=no&sig=c04623d46a754dc62ff52527f6e82d1c82da608e82821693fdacffe1bdae69f6&dest=https%3A%2F%2Fdoctoreto.com%2Fdoctor%2Fdr-hamid-haghshenas%2FqLJgQM | D26: https://adserver.doctoreto.com/www/images/847de085a6cb19dec2b106987063933b.webp | E26: 1404/09/19 | F26: 1404/12/19
A27: Dr - Hossein Abtahi | B27: Dr - Hossein Abtahi II | C27: https://adserver.doctoreto.com/www/delivery/cl.php?bannerid=504&zoneid=0&log=no&sig=8695cedae9e8e13520a13bd25d2ca72bc179ed75045713e5f9e760d41f4b02ab&dest=https%3A%2F%2Fdoctoreto.com%2Fdoctor%2Fdr-seyed-hossein-abtahi%2FMLzKQz%3FsearchedFrom%3DheaderAutoFill | D27: https://adserver.doctoreto.com/www/images/1beb47a0d5184cabc26afe42d7f37fdb.gif | E27: 1404/10/03 | F27: 1405/01/03
A28: Dr - Hossein Abtahi | B28: Dr Hossein Abtahi | C28: https://adserver.doctoreto.com/www/delivery/cl.php?bannerid=500&zoneid=0&log=no&sig=77e1a056194b2ea28c4fbaa140dbb98fa52a1efdc4e4f8582eb2211c1864ff76&dest=https%3A%2F%2Fdoctoreto.com%2Fdoctor%2Fdr-seyed-hossein-abtahi%2FMLzKQz%3FsearchedFrom%3DheaderAutoFill | D28: https://adserver.doctoreto.com/www/images/609f853e756b51b8875f0afd81d202b7.webp | E28: 1404/10/03 | F28: 1405/01/03
A29: DR - Masoumeh Mahboudi | B29: Dr Masoumeh Mahboudi | C29: https://adserver.doctoreto.com/www/delivery/cl.php?bannerid=510&zoneid=0&log=no&sig=c96b87a8558666da8c6a4e94dd5418378fd4be2d52df771fb08d8e413a6ff95b&dest=https%3A%2F%2Fdoctoreto.com%2Fdoctor%2Fmaasoomeh-mehboodi%2FMLjxdP | D29: https://adserver.doctoreto.com/www/images/1ebaaaabb45a0759491dee721d192c32.webp | E29: 1404/10/08 | F29: 1405/01/08
A30: Dr - Roshanak ghavas | B30: Dr - Roshanak Ghavas | C30: https://adserver.doctoreto.com/www/delivery/cl.php?bannerid=647&zoneid=0&log=no&sig=ac97c8abcd6778efce2c74ce69e92084a7cae417d269ff1f241ae1d565e1f5b4&dest=https%3A%2F%2Fdoctoreto.com%2Fdoctor%2Fdr-rowshanak-ghavvas-owhadi%2FGnBdmd | D30: https://adserver.doctoreto.com/www/images/a30fb9aacf5ec600fd189b04956ef1a2.jpg | E30: 1405/03/10 | F30: 1405/06/10
A31: Dr - Shirin - Moghimi | B31: Dr Shirin Moghimi | C31: https://adserver.doctoreto.com/www/delivery/cl.php?bannerid=522&zoneid=0&log=no&sig=2eb51a6504ac3f31ebfd53304e87f559802db931ee24b26b045f34555b04ddca&dest=https%3A%2F%2Fdoctoreto.com%2Fdoctor%2Fdr-shirin-moghimi%2FqdlAKp | D31: https://adserver.doctoreto.com/www/images/5a043b3e422492214f24b132980dc0c0.webp | E31: 1405/04/10 | F31: 1405/07/10
A32: DR Ali NaserBakhT | B32: DR NaserBakhT | C32: https://adserver.doctoreto.com/www/delivery/cl.php?bannerid=701&zoneid=0&log=no&sig=441e69c959aeff1b8fa066fa72b44db4cb426a41af3a37a9c70b8173a3d2991f&dest=https%3A%2F%2Fdoctoreto.com%2Fdoctor%2Fdr-ali-naser-bakht%2FGDmvvM | D32: https://adserver.doctoreto.com/www/images/3fe8e8e1c22a5a9491ecc16e32a75913.gif | E32: 1405/03/26 | F32: 1405/06/26 | G32: Ellie | H32: =VLOOKUP(A32,Sheet2!A:E,5,0) -> 132000000
A33: DR Ali NaserBakhT | B33: Dr NaserBakht LeaderBoard | C33: https://adserver.doctoreto.com/www/delivery/cl.php?bannerid=721&zoneid=0&log=no&sig=54fc19e54018b3d8b036b9408f23793cca6b970b47f784b83e59e49e4e8d952a&dest=https%3A%2F%2Fdoctoreto.com%2Fdoctor%2Fdr-ali-naser-bakht%2FGDmvvM | D33: https://adserver.doctoreto.com/www/images/8eefa0bf75aa9e297bc58b9676c4b42f.gif | E33: 1405/03/26 | F33: 1405/06/26 | G33: Ellie | H33: =VLOOKUP(A33,Sheet2!A:E,5,0) -> 132000000
A34: DR Ali Saeedi | B34: Dr Ali Saeedi | C34: https://adserver.doctoreto.com/www/delivery/cl.php?bannerid=742&zoneid=0&log=no&sig=c8cfdda714123f111dded2cb1726b0723b4b923918ad2e9bfee4288c4d7ff875&dest=https%3A%2F%2Fdoctoreto.com%2Fdoctor%2Fdr-ali-saeidi%2FGxbJLZ | D34: https://adserver.doctoreto.com/www/images/0896edcd67ed7cf9420169d0541d5c7f.gif | E34: 1405/04/02 | F34: 1405/07/02 | G34: Shahrzad | H34: =VLOOKUP(A34,Sheet2!A:E,5,0) -> 55000000
A35: Dr Amir Azizi | B35: Dr Amir Azizi | C35: https://adserver.doctoreto.com/www/delivery/cl.php?bannerid=763&zoneid=0&log=no&sig=57b0a831138eb3a70b70d278f495e97f3a799403cbc1bc45244c7c25dc40a37f&dest=https%3A%2F%2Fdoctoreto.com%2Fdoctor%2Fdr-amir-azizii%2FMmzgdO | D35: https://adserver.doctoreto.com/www/images/8fcb7e425f67d18a485d4113e09abc8c.gif | E35: =VLOOKUP(B35,Sheet2!A:C,3,0) -> 1405/04/06 | F35: 1405/07/08 | G35: =VLOOKUP(A35,Sheet2!A:B,2,0) -> Sanam | H35: =VLOOKUP(A35,Sheet2!A:E,5,0) -> 30600000
A36: Dr Aref Fatehi | B36: DR Aref Fatehi | C36: https://adserver.doctoreto.com/www/delivery/cl.php?bannerid=1152&zoneid=0&log=no&sig=7a2a5ac05acb5a72d12c2c7854790b39f9bb6e471d9705ad63aa9a5e076ccd5e&dest=https%3A%2F%2Fdoctoreto.com%2Fdoctor%2Fdr-aref-fatehi%2FMWLmnZ | D36: https://adserver.doctoreto.com/www/images/08e2d41645191b0360098de47bfe59b7.gif | E36: =VLOOKUP(A36,Sheet2!A:C,3,0) -> 1405/05/24 | F36: =VLOOKUP(A36,Sheet2!A:D,4,0) -> 1405/08/24 | G36: =VLOOKUP(A36,Sheet2!A:B,2,0) -> Nastaran | H36: =VLOOKUP(A36,Sheet2!A:E,5,0) -> 6600000
A37: Dr AssaEi | B37: Dr Asaei | C37: https://adserver.doctoreto.com/www/delivery/cl.php?bannerid=1172&zoneid=0&log=no&sig=0d0a17b75dfd24418b5078bd952e800c98287db76d3646461f8ff48c141ba62d&dest=https%3A%2F%2Fdoctoreto.com%2Fdoctor%2Fdr-seyed-hamid-asaei%2FqjxDJM | D37: https://adserver.doctoreto.com/www/images/584855956a8862081c65f0c53c482205.gif | E37: =VLOOKUP(A37,Sheet2!A:C,3,0) -> 1405/05/26 | F37: =VLOOKUP(A37,Sheet2!A:D,4,0) -> 1405/08/26 | G37: =VLOOKUP(A37,Sheet2!A:B,2,0) -> Nastaran | H37: =VLOOKUP(A37,Sheet2!A:E,5,0) -> 20000000
A38: DR Ata Heydari | B38: Dr Ata Heydari | C38: https://adserver.doctoreto.com/www/delivery/cl.php?bannerid=557&zoneid=0&log=no&sig=7f58823f66fb3542e45b94d3e4f5229a914351580410eb9f49acfa7a25aeac77&dest=https%3A%2F%2Fdoctoreto.com%2Fdoctor%2Fdr-ata-allah-heydari%2FGQaAvG | D38: https://adserver.doctoreto.com/www/images/1b3c57ec008a30b74d0946a4e88f8891.webp | E38: =VLOOKUP(A38,Sheet2!A:C,3,0) -> 0 | F38: =VLOOKUP(A38,Sheet2!A:D,4,0) -> 0 | G38: =VLOOKUP(A38,Sheet2!A:B,2,0) -> Naser | H38: =VLOOKUP(A38,Sheet2!A:E,5,0) -> 150000000
A39: Dr Atefe Faramarzi | B39: Dr Atefe Faramarzi PLP | C39: https://adserver.doctoreto.com/www/delivery/cl.php?bannerid=1115&zoneid=0&log=no&sig=ab3546326e50c72085d77a1e84b732c7cb897f563d30b6d22622314591238188&dest=https%3A%2F%2Fdoctoreto.com%2Fdoctor%2Fdr-atefeh-faramarzi%2FGnJaPG | D39: https://adserver.doctoreto.com/www/images/4f71909ccee7bc35f0480c075a948488.gif | E39: =VLOOKUP(A39,Sheet2!A:C,3,0) -> 1405/05/05 | F39: =VLOOKUP(A39,Sheet2!A:D,4,0) -> 1405/08/05 | G39: =VLOOKUP(A39,Sheet2!A:B,2,0) -> Naser | H39: =VLOOKUP(A39,Sheet2!A:E,5,0) -> 135000000
A40: DR Azadeh Khalajian | B40: DR Azadeh KhalaJian | C40: https://adserver.doctoreto.com/www/delivery/cl.php?bannerid=731&zoneid=0&log=no&sig=3cbbfaa372ead48a505abd82774a8df655e7362c84aa47f7d3989972347e68f9&dest=https%3A%2F%2Fdoctoreto.com%2Fdoctor%2Fdr-azadeh-khalajian%2FMkAPOq | D40: https://adserver.doctoreto.com/www/images/d9e092b9849657c181499a8c1465a8b6.gif | E40: =VLOOKUP(A40,Sheet2!A:C,3,0) -> 1405/03/15 | F40: =VLOOKUP(A40,Sheet2!A:D,4,0) -> 1405/06/15 | G40: =VLOOKUP(A40,Sheet2!A:B,2,0) -> Sanam | H40: =VLOOKUP(A40,Sheet2!A:E,5,0) -> 60000000
...

Sheet Sheet2
A1: Campaign Name | B1: Account Manager | C1: Start Date | D1: End Date | E1: Price
A2: Dr Amir Azizi | B2: Sanam | C2: 1405/04/06 | D2: 1405/07/06 | E2: 30600000
A3: DR Ali Saeedi | B3: shahrzad | C3: 1405/03/26 | D3: 1405/06/25 | E3: 55000000
A4: DR Ali NaserBakhT | B4: elahe | C4: 1405/02/29 | D4: 1405/05/29 | E4: 132000000
A5: Dr AssaEi | B5: Nastaran | C5: 1405/05/26 | D5: 1405/08/26 | E5: 20000000
A6: DR Azadeh Khalajian | B6: Sanam | C6: 1405/03/15 | D6: 1405/06/15 | E6: 60000000
A7: Dr Atefe Faramarzi | B7: Naser | C7: 1405/05/05 | D7: 1405/08/05 | E7: 135000000
A8: DR Ata Heydari | B8: Naser | E8: 150000000
A9: Dr Azhie | B9: Naser | C9: 1405/05/19 | D9: 1405/08/19 | E9: 140000000
A10: Dr Azadeh MirMaasoumi | B10: Sara | C10: 1405/03/16 | D10: 1405/05/16 | E10: 45000000
A11: Dr Homa Sharifi | B11: Sara | C11: 1405/04/08 | D11: 1405/07/08 | E11: 27000000
A12: Dr Zarin BadiNi | B12: Sanam | C12: 1405/04/29 | D12: 1405/07/29 | E12: 240000000
A13: DR Zeynab Tavana | B13: Nastaran | C13: 1405/05/19 | D13: 1405/08/19 | E13: 8800000
A14: Dr. Farshad Sadeghi | B14: Sara | C14: 1405/04/10 | D14: 1405/07/10 | E14: 60000000
A15: Dr. Amir Bastani | B15: Nastaran | C15: 1405/03/09 | D15: 1405/06/09 | E15: 36000000
A16: Dr. Ghazi | B16: Naser | C16: 1405/06/04 | D16: 1405/09/04 | E16: 427000000
A17: Dr. Hadi Mansouri | B17: Nastaran | C17: 1405/04/02 | D17: 1405/07/02 | E17: 46200000
A18: Dr. Izadpanah | B18: Sara | C18: 1405/04/28 | D18: 1405/07/28 | E18: 75000000
A19: Dr. Hengame Mehrfar | B19: shahrzad | C19: 1405/05/25 | D19: 1405/08/25 | E19: 46200000
A20: Dr. Mohammad Borzoyi | B20: shahrzad | C20: 1405/03/04 | D20: 1405/06/04 | E20: 49500000
... A52: Dr Atefe Faramarzi | B52: Naser | C52: 1405/05/05 | D52: 1405/08/05 | E52: 135000000
A53: DR Ata Heydari | B53: Naser | E53: 150000000
A54: Dr Azhie | B54: Naser | C54: 1405/05/19 | D54: 1405/08/19 | E54: 140000000
A55: Dr Azadeh MirMaasoumi | B55: Sara | C55: 1405/03/16 | D55: 1405/05/16 | E55: 45000000
A56: Dr Homa Sharifi | B56: Sara | C56: 1405/04/08 | D56: 1405/07/08 | E56: 27000000
A57: Dr Zarin BadiNi | B57: Sanam | C57: 1405/04/29 | D57: 1405/07/29 | E57: 240000000
A58: DR Zeynab Tavana | B58: Nastaran | C58: 1405/05/19 | D58: 1405/08/19 | E58: 8800000
A59: Dr. Farshad Sadeghi | B59: Sara | C59: 1405/04/10 | D59: 1405/07/10 | E59: 60000000
A60: Dr. Amir Bastani | B60: Nastaran | C60: 1405/03/09 | D60: 1405/06/09 | E60: 36000000
A61: Dr. Ghazi | B61: Naser | C61: 1405/06/04 | D61: 1405/09/04 | E61: 427000000
A62: Dr. Hadi Mansouri | B62: Nastaran | C62: 1405/04/02 | D62: 1405/07/02 | E62: 46200000
A63: Dr. Izadpanah | B63: Sara | C63: 1405/04/28 | D63: 1405/07/28 | E63: 75000000
A64: Dr. Hengame Mehrfar | B64: Shahrzad | C64: 1405/05/25 | D64: 1405/08/25 | E64: 46200000
A65: Dr. Mohammad Borzoyi | B65: Shahrzad | C65: 1405/03/04 | D65: 1405/06/04 | E65: 49500000
... A176: Dr. Yazdan Panah | B176: Shahrzad | C176: 1405/04/10 | D176: 1405/07/10 | E176: 39600000
